Workbook
Name Slicer_Financial_Year: #N/A
Name Slicer_Type: #N/A
Name Slicer_State: #N/A
Name Slicer_Category: #N/A

Sheet Main Dashboard
B1: KMART | Store & Online sales performance | AO1: ="Data: "&TEXT(MIN(KMART_DATA[Date]),"mmm yyyy")&" to "&TEXT(MAX(KMART_DATA[Date]),"mmm yyyy") -> Data: Jan 2024 to Dec 2025
U2: Kmart Sales Dashboard | BI2: Click a slicer button to filter every KPI and chart. Ctrl+click to pick several; the funnel-x icon clears a slicer.
B4: TOTAL SALES | L4: AVERAGE SALE
B5: =IFERROR(GETPIVOTDATA("Total Sales",Pivots!$A$3),0) -> 3186258.5 | L5: =IFERROR(GETPIVOTDATA("Total Sales",Pivots!$A$3)/GETPIVOTDATA("Transactions",Pivots!$A$3),0) -> 707.27
B6: =TEXT(IFERROR(GETPIVOTDATA("Transactions",Pivots!$A$3),0),"#,##0")&" transactions" -> 4,505 transactions | L6: ="per transaction" -> per transaction
BR10: Sales trend by state
BR11: State | BU11: Sales | BX11: Trend
BR12: NSW | BU12: =IFERROR(GETPIVOTDATA("Total Sales",Pivots!$AQ$3,"State",BR12),0) -> 1165603.5
BR13: VIC | BU13: =IFERROR(GETPIVOTDATA("Total Sales",Pivots!$AQ$3,"State",BR13),0) -> 825449.32
BR14: QLD | BU14: =IFERROR(GETPIVOTDATA("Total Sales",Pivots!$AQ$3,"State",BR14),0) -> 603864.98
BR15: WA | BU15: =IFERROR(GETPIVOTDATA("Total Sales",Pivots!$AQ$3,"State",BR15),0) -> 312583.22
BR16: SA | BU16: =IFERROR(GETPIVOTDATA("Total Sales",Pivots!$AQ$3,"State",BR16),0) -> 112716.27
BR17: NT | BU17: =IFERROR(GETPIVOTDATA("Total Sales",Pivots!$AQ$3,"State",BR17),0) -> 67846.81
BR18: TAS | BU18: =IFERROR(GETPIVOTDATA("Total Sales",Pivots!$AQ$3,"State",BR18),0) -> 59512.45
BR19: ACT | BU19: =IFERROR(GETPIVOTDATA("Total Sales",Pivots!$AQ$3,"State",BR19),0) -> 38681.96
B21: ="Source: KMART DATA table ("&TEXT(ROWS(KMART_DATA[Sales]),"#,##0")&" rows). Pivot tables refresh automatically when the file opens; after editing data use Data > Refresh All. Category-mix chart shows the top 10 suburbs by sales for the current filters." -> Source: KMART DATA table (4,505 rows). Pivot tables refresh automatically when the file opens; after editing data use Data > Refresh All. Category-mix chart shows the top 10 suburbs by sales for the current filters.

Sheet KMART DATA
A1: Date | B1: Financial Year | C1: Month | D1: Type | E1: Suburb | F1: State | G1: Full State | H1: Postcode | I1: Country | J1: Manager | K1: Category | L1: Buyer | M1: Sales
A2: 45292 | B2: ="FY"&(YEAR(KMART_DATA[[#This Row],[Date]])+(MONTH(KMART_DATA[[#This Row],[Date]])>=7)-1)&"-"&RIGHT(YEAR(KMART_DATA[[#This Row],[Date]])+(MONTH(KMART_DATA[[#This Row],[Date]])>=7),2) -> FY2023-24 | C2: =YEAR(KMART_DATA[[#This Row],[Date]])&"-"&TEXT(MONTH(KMART_DATA[[#This Row],[Date]]),"00") -> 2024-01 | D2: Store | E2: Yeppoon | F2: QLD | G2: =IFERROR(INDEX({"Australian Capital Territory","New South Wales","Northern Territory","Queensland","South Australia","Tasmania","Victoria","Western Australia"},MATCH(KMART_DATA[[#This Row],[State]],{"ACT","NSW","NT","QLD","SA","TAS","VIC","WA"},0)),KMART_DATA[[#This Row],[State]]) -> Queensland | H2: 4703 | I2: Australia | J2: Amber Ward | K2: Electronics & Entertainment | L2: Maggie Mayer | M2: 9.98
A3: 45292 | B3: ="FY"&(YEAR(KMART_DATA[[#This Row],[Date]])+(MONTH(KMART_DATA[[#This Row],[Date]])>=7)-1)&"-"&RIGHT(YEAR(KMART_DATA[[#This Row],[Date]])+(MONTH(KMART_DATA[[#This Row],[Date]])>=7),2) -> FY2023-24 | C3: =YEAR(KMART_DATA[[#This Row],[Date]])&"-"&TEXT(MONTH(KMART_DATA[[#This Row],[Date]]),"00") -> 2024-01 | D3: Store | E3: Warrnambool | F3: VIC | G3: =IFERROR(INDEX({"Australian Capital Territory","New South Wales","Northern Territory","Queensland","South Australia","Tasmania","Victoria","Western Australia"},MATCH(KMART_DATA[[#This Row],[State]],{"ACT","NSW","NT","QLD","SA","TAS","VIC","WA"},0)),KMART_DATA[[#This Row],[State]]) -> Victoria | H3: 3280 | I3: Australia | J3: Jerry Fulton | K3: Accessories | L3: Sara Ferrell | M3: 23.92
A4: 45292 | B4: ="FY"&(YEAR(KMART_DATA[[#This Row],[Date]])+(MONTH(KMART_DATA[[#This Row],[Date]])>=7)-1)&"-"&RIGHT(YEAR(KMART_DATA[[#This Row],[Date]])+(MONTH(KMART_DATA[[#This Row],[Date]])>=7),2) -> FY2023-24 | C4: =YEAR(KMART_DATA[[#This Row],[Date]])&"-"&TEXT(MONTH(KMART_DATA[[#This Row],[Date]]),"00") -> 2024-01 | D4: Store | E4: Woodville | F4: SA | G4: =IFERROR(INDEX({"Australian Capital Territory","New South Wales","Northern Territory","Queensland","South Australia","Tasmania","Victoria","Western Australia"},MATCH(KMART_DATA[[#This Row],[State]],{"ACT","NSW","NT","QLD","SA","TAS","VIC","WA"},0)),KMART_DATA[[#This Row],[State]]) -> South Australia | H4: 5011 | I4: Australia | J4: Ray Watson | K4: Baby & Nursery | L4: Amy Buchanan | M4: 35.48
A5: 45292 | B5: ="FY"&(YEAR(KMART_DATA[[#This Row],[Date]])+(MONTH(KMART_DATA[[#This Row],[Date]])>=7)-1)&"-"&RIGHT(YEAR(KMART_DATA[[#This Row],[Date]])+(MONTH(KMART_DATA[[#This Row],[Date]])>=7),2) -> FY2023-24 | C5: =YEAR(KMART_DATA[[#This Row],[Date]])&"-"&TEXT(MONTH(KMART_DATA[[#This Row],[Date]]),"00") -> 2024-01 | D5: Online | E5: Yeppoon | F5: QLD | G5: =IFERROR(INDEX({"Australian Capital Territory","New South Wales","Northern Territory","Queensland","South Australia","Tasmania","Victoria","Western Australia"},MATCH(KMART_DATA[[#This Row],[State]],{"ACT","NSW","NT","QLD","SA","TAS","VIC","WA"},0)),KMART_DATA[[#This Row],[State]]) -> Queensland | H5: 4703 | I5: Australia | J5: Amber Ward | K5: Beauty & Personal Care | L5: Chester George | M5: 184.87
A6: 45292 | B6: ="FY"&(YEAR(KMART_DATA[[#This Row],[Date]])+(MONTH(KMART_DATA[[#This Row],[Date]])>=7)-1)&"-"&RIGHT(YEAR(KMART_DATA[[#This Row],[Date]])+(MONTH(KMART_DATA[[#This Row],[Date]])>=7),2) -> FY2023-24 | C6: =YEAR(KMART_DATA[[#This Row],[Date]])&"-"&TEXT(MONTH(KMART_DATA[[#This Row],[Date]]),"00") -> 2024-01 | D6: Store | E6: Broome | F6: WA | G6: =IFERROR(INDEX({"Australian Capital Territory","New South Wales","Northern Territory","Queensland","South Australia","Tasmania","Victoria","Western Australia"},MATCH(KMART_DATA[[#This Row],[State]],{"ACT","NSW","NT","QLD","SA","TAS","VIC","WA"},0)),KMART_DATA[[#This Row],[State]]) -> Western Australia | H6: 6725 | I6: Australia | J6: John Harper | K6: Electronics & Entertainment | L6: Maggie Mayer | M6: 635.04
A7: 45292 | B7: ="FY"&(YEAR(KMART_DATA[[#This Row],[Date]])+(MONTH(KMART_DATA[[#This Row],[Date]])>=7)-1)&"-"&RIGHT(YEAR(KMART_DATA[[#This Row],[Date]])+(MONTH(KMART_DATA[[#This Row],[Date]])>=7),2) -> FY2023-24 | C7: =YEAR(KMART_DATA[[#This Row],[Date]])&"-"&TEXT(MONTH(KMART_DATA[[#This Row],[Date]]),"00") -> 2024-01 | D7: Store | E7: Rosny Park | F7: TAS | G7: =IFERROR(INDEX({"Australian Capital Territory","New South Wales","Northern Territory","Queensland","South Australia","Tasmania","Victoria","Western Australia"},MATCH(KMART_DATA[[#This Row],[State]],{"ACT","NSW","NT","QLD","SA","TAS","VIC","WA"},0)),KMART_DATA[[#This Row],[State]]) -> Tasmania | H7: 7018 | I7: Australia | J7: Simone Prior | K7: Beauty & Personal Care | L7: Chester George | M7: 893.23
A8: 45292 | B8: ="FY"&(YEAR(KMART_DATA[[#This Row],[Date]])+(MONTH(KMART_DATA[[#This Row],[Date]])>=7)-1)&"-"&RIGHT(YEAR(KMART_DATA[[#This Row],[Date]])+(MONTH(KMART_DATA[[#This Row],[Date]])>=7),2) -> FY2023-24 | C8: =YEAR(KMART_DATA[[#This Row],[Date]])&"-"&TEXT(MONTH(KMART_DATA[[#This Row],[Date]]),"00") -> 2024-01 | D8: Online | E8: Toombul | F8: QLD | G8: =IFERROR(INDEX({"Australian Capital Territory","New South Wales","Northern Territory","Queensland","South Australia","Tasmania","Victoria","Western Australia"},MATCH(KMART_DATA[[#This Row],[State]],{"ACT","NSW","NT","QLD","SA","TAS","VIC","WA"},0)),KMART_DATA[[#This Row],[State]]) -> Queensland | H8: 4012 | I8: Australia | J8: Terri Wright | K8: Toys & Outdoor Play | L8: Howard Wright | M8: 1180.27
A9: 45292 | B9: ="FY"&(YEAR(KMART_DATA[[#This Row],[Date]])+(MONTH(KMART_DATA[[#This Row],[Date]])>=7)-1)&"-"&RIGHT(YEAR(KMART_DATA[[#This Row],[Date]])+(MONTH(KMART_DATA[[#This Row],[Date]])>=7),2) -> FY2023-24 | C9: =YEAR(KMART_DATA[[#This Row],[Date]])&"-"&TEXT(MONTH(KMART_DATA[[#This Row],[Date]]),"00") -> 2024-01 | D9: Store | E9: North Lakes | F9: QLD | G9: =IFERROR(INDEX({"Australian Capital Territory","New South Wales","Northern Territory","Queensland","South Australia","Tasmania","Victoria","Western Australia"},MATCH(KMART_DATA[[#This Row],[State]],{"ACT","NSW","NT","QLD","SA","TAS","VIC","WA"},0)),KMART_DATA[[#This Row],[State]]) -> Queensland | H9: 4509 | I9: Australia | J9: Ricky Wilkinson | K9: Baby & Nursery | L9: Amy Buchanan | M9: 1354.21
A10: 45293 | B10: ="FY"&(YEAR(KMART_DATA[[#This Row],[Date]])+(MONTH(KMART_DATA[[#This Row],[Date]])>=7)-1)&"-"&RIGHT(YEAR(KMART_DATA[[#This Row],[Date]])+(MONTH(KMART_DATA[[#This Row],[Date]])>=7),2) -> FY2023-24 | C10: =YEAR(KMART_DATA[[#This Row],[Date]])&"-"&TEXT(MONTH(KMART_DATA[[#This Row],[Date]]),"00") -> 2024-01 | D10: Store | E10: Geraldton | F10: WA | G10: =IFERROR(INDEX({"Australian Capital Territory","New South Wales","Northern Territory","Queensland","South Australia","Tasmania","Victoria","Western Australia"},MATCH(KMART_DATA[[#This Row],[State]],{"ACT","NSW","NT","QLD","SA","TAS","VIC","WA"},0)),KMART_DATA[[#This Row],[State]]) -> Western Australia | H10: 6530 | I10: Australia | J10: John Harper | K10: Beauty & Personal Care | L10: Chester George | M10: 12.99
A11: 45293 | B11: ="FY"&(YEAR(KMART_DATA[[#This Row],[Date]])+(MONTH(KMART_DATA[[#This Row],[Date]])>=7)-1)&"-"&RIGHT(YEAR(KMART_DATA[[#This Row],[Date]])+(MONTH(KMART_DATA[[#This Row],[Date]])>=7),2) -> FY2023-24 | C11: =YEAR(KMART_DATA[[#This Row],[Date]])&"-"&TEXT(MONTH(KMART_DATA[[#This Row],[Date]]),"00") -> 2024-01 | D11: Store | E11: Southport | F11: QLD | G11: =IFERROR(INDEX({"Australian Capital Territory","New South Wales","Northern Territory","Queensland","South Australia","Tasmania","Victoria","Western Australia"},MATCH(KMART_DATA[[#This Row],[State]],{"ACT","NSW","NT","QLD","SA","TAS","VIC","WA"},0)),KMART_DATA[[#This Row],[State]]) -> Queensland | H11: 4215 | I11: Australia | J11: Ricky Wilkinson | K11: Party & Gift Wrap | L11: Chris Monroe | M11: 318.18
A12: 45293 | B12: ="FY"&(YEAR(KMART_DATA[[#This Row],[Date]])+(MONTH(KMART_DATA[[#This Row],[Date]])>=7)-1)&"-"&RIGHT(YEAR(KMART_DATA[[#This Row],[Date]])+(MONTH(KMART_DATA[[#This Row],[Date]])>=7),2) -> FY2023-24 | C12: =YEAR(KMART_DATA[[#This Row],[Date]])&"-"&TEXT(MONTH(KMART_DATA[[#This Row],[Date]]),"00") -> 2024-01 | D12: Store | E12: Ballina | F12: NSW | G12: =IFERROR(INDEX({"Australian Capital Territory","New South Wales","Northern Territory","Queensland","South Australia","Tasmania","Victoria","Western Australia"},MATCH(KMART_DATA[[#This Row],[State]],{"ACT","NSW","NT","QLD","SA","TAS","VIC","WA"},0)),KMART_DATA[[#This Row],[State]]) -> New South Wales | H12: 2478 | I12: Australia | J12: Claire Bridges | K12: Clothing & Fashion | L12: Bruce Curran | M12: 526.89
A13: 45293 | B13: ="FY"&(YEAR(KMART_DATA[[#This Row],[Date]])+(MONTH(KMART_DATA[[#This Row],[Date]])>=7)-1)&"-"&RIGHT(YEAR(KMART_DATA[[#This Row],[Date]])+(MONTH(KMART_DATA[[#This Row],[Date]])>=7),2) -> FY2023-24 | C13: =YEAR(KMART_DATA[[#This Row],[Date]])&"-"&TEXT(MONTH(KMART_DATA[[#This Row],[Date]]),"00") -> 2024-01 | D13: Store | E13: Penrith | F13: NSW | G13: =IFERROR(INDEX({"Australian Capital Territory","New South Wales","Northern Territory","Queensland","South Australia","Tasmania","Victoria","Western Australia"},MATCH(KMART_DATA[[#This Row],[State]],{"ACT","NSW","NT","QLD","SA","TAS","VIC","WA"},0)),KMART_DATA[[#This Row],[State]]) -> New South Wales | H13: 2750 | I13: Australia | J13: John Gardner | K13: Toys & Outdoor Play | L13: Howard Wright | M13: 551.43
... A4506: 46022 | B4506: ="FY"&(YEAR(KMART_DATA[[#This Row],[Date]])+(MONTH(KMART_DATA[[#This Row],[Date]])>=7)-1)&"-"&RIGHT(YEAR(KMART_DATA[[#This Row],[Date]])+(MONTH(KMART_DATA[[#This Row],[Date]])>=7),2) -> FY2025-26 | C4506: =YEAR(KMART_DATA[[#This Row],[Date]])&"-"&TEXT(MONTH(KMART_DATA[[#This Row],[Date]]),"00") -> 2025-12 | D4506: Store | E4506: Orange | F4506: NSW | G4506: =IFERROR(INDEX({"Australian Capital Territory","New South Wales","Northern Territory","Queensland","South Australia","Tasmania","Victoria","Western Australia"},MATCH(KMART_DATA[[#This Row],[State]],{"ACT","NSW","NT","QLD","SA","TAS","VIC","WA"},0)),KMART_DATA[[#This Row],[State]]) -> New South Wales | H4506: 2800 | I4506: Australia | J4506: John Gardner | K4506: Home & Living | L4506: Elizabeth Gentry | M4506: 7691.87

Sheet Pivots
A1: State x month (feeds sparklines) | E1: Total sales over time | K1: Avg sales over time | O1: Sales by category | S1: Sales by category - proportions (top 10 suburbs) | AG1: Online Vs Store | AJ1: Sales by manager | AM1: Sales by buyers - online | AQ1: Sales by state
A3: Total Sales | B3: Transactions | E3: Total Sales | F3: Type | K3: Month | L3: Avg Sale | O3: Category | P3: Total Sales | S3: Total Sales | T3: Category | AG3: Type | AH3: Total Sales | AJ3: Manager | AK3: Total Sales | AM3: Type | AN3: Online | AQ3: State | AR3: Total Sales
A4: 3186258.5 | B4: 4505 | E4: Month | F4: Online | G4: Store | H4: Grand Total | K4: 2024-01 | L4: 710.84908 | O4: Party & Gift Wrap | P4: 61587.13 | S4: Suburb | T4: Accessories | U4: Baby & Nursery | V4: Beauty & Personal Care | W4: Clothing & Fashion | X4: Electronics & Entertainment | Y4: Footwear | Z4: Home & Living | AA4: Party & Gift Wrap | AB4: Stationery & Office Supplies | AC4: Toys & Outdoor Play | AD4: Grand Total | AG4: Online | AH4: 658115.49 | AJ4: Alex Nash | AK4: 32930.34 | AQ4: ACT | AR4: 38681.96
E5: 2024-01 | F5: 17665.07 | G5: 113131.16 | H5: 130796.23 | K5: 2024-02 | L5: 704.94942 | O5: Stationery & Office Supplies | P5: 66885.88 | S5: Castle Hill | T5: 1347.13 | U5: 4377.85 | V5: 8610.5 | W5: 13106.26 | X5: 4283.33 | Y5: 10777.39 | Z5: 17481.19 | AA5: 1039.55 | AB5: 1677.76 | AC5: 9090.8 | AD5: 71791.76 | AG5: Store | AH5: 2528143 | AJ5: Caroline Tucker | AK5: 54140.09 | AM5: Buyer | AN5: Total Sales | AQ5: TAS | AR5: 59512.45
E6: 2024-02 | F6: 12622.54 | G6: 119907.95 | H6: 132530.49 | K6: 2024-03 | L6: 616.26219 | O6: Accessories | P6: 87457.9 | S6: Armidale | T6: 1316.52 | U6: 4593.16 | V6: 8246.4 | W6: 10246.11 | X6: 3735.07 | Y6: 9216.48 | Z6: 14923.91 | AA6: 1856.47 | AB6: 2517.72 | AC6: 16456.41 | AD6: 73108.25 | AG6: Grand Total | AH6: 3186258.5 | AJ6: Simone Prior | AK6: 59512.45 | AM6: Chris Monroe | AN6: 12738.55 | AQ6: NT | AR6: 67846.81
E7: 2024-03 | F7: 30766.69 | G7: 90020.7 | H7: 120787.39 | K7: 2024-04 | L7: 832.6021 | O7: Electronics & Entertainment | P7: 164706.16 | S7: Ballarat | T7: 1761.49 | U7: 5484.72 | V7: 7371.37 | W7: 14638.28 | X7: 2590.07 | Y7: 10116.58 | Z7: 18923.99 | AA7: 1734.45 | AB7: 442.78 | AC7: 11353.6 | AD7: 74417.33 | AJ7: Amber Ward | AK7: 63037 | AM7: Ella Hickman | AN7: 15631.69 | AQ7: SA | AR7: 112716.27
E8: 2024-04 | F8: 27919.52 | G8: 142763.91 | H8: 170683.43 | K8: 2024-05 | L8: 669.4972 | O8: Baby & Nursery | P8: 219917.08 | S8: Dubbo | T8: 2305.12 | U8: 3130.79 | V8: 7774.61 | W8: 10121.09 | X8: 2326.93 | Y8: 6995.65 | Z8: 23651.68 | AA8: 1367 | AB8: 2066.48 | AC8: 14999.57 | AD8: 74738.92 | AJ8: Owen Pierce | AK8: 67318.87 | AM8: Sara Ferrell | AN8: 23548.91 | AQ8: WA | AR8: 312583.22
E9: 2024-05 | F9: 32337.62 | G9: 92188.86 | H9: 124526.48 | K9: 2024-06 | L9: 949.58085 | O9: Beauty & Personal Care | P9: 360173.77 | S9: Alexandria | T9: 2105.78 | U9: 3812.26 | V9: 9132.92 | W9: 11790.65 | X9: 2501.3 | Y9: 10899.75 | Z9: 18865.28 | AA9: 3222.9 | AB9: 2003.34 | AC9: 11128.74 | AD9: 75462.92 | AJ9: Tom McKenzie | AK9: 67634.36 | AM9: Maggie Mayer | AN9: 39203.43 | AQ9: QLD | AR9: 603864.98
E10: 2024-06 | F10: 42988.65 | G10: 145977.94 | H10: 188966.59 | K10: 2024-07 | L10: 692.83026 | O10: Footwear | P10: 381623.78 | S10: Albany | T10: 2067.24 | U10: 4309.11 | V10: 7818.19 | W10: 12232.58 | X10: 4314.61 | Y10: 12561.76 | Z10: 18243.11 | AA10: 2115.46 | AB10: 1518.57 | AC10: 10926.36 | AD10: 76106.99 | AJ10: Michael Carney | AK10: 67846.81 | AM10: Amy Buchanan | AN10: 45816.3 | AQ10: VIC | AR10: 825449.32
E11: 2024-07 | F11: 23888.63 | G11: 109827.61 | H11: 133716.24 | K11: 2024-08 | L11: 729.58689 | O11: Toys & Outdoor Play | P11: 549402.55 | S11: Underwood | T11: 1666.9 | U11: 5566.92 | V11: 6057.08 | W11: 12294.73 | X11: 3533.52 | Y11: 13926.98 | Z11: 17731.54 | AA11: 1406.9 | AB11: 2840.44 | AC11: 12193.57 | AD11: 77218.58 | AJ11: Ray Watson | AK11: 79785.93 | AM11: Richard Carr | AN11: 69084.55 | AQ11: NSW | AR11: 1165603.5
E12: 2024-08 | F12: 31904.03 | G12: 120579.63 | H12: 152483.66 | K12: 2024-09 | L12: 713.78203 | O12: Home & Living | P12: 608024.39 | S12: Chadstone | T12: 1850.6 | U12: 5103.5 | V12: 9284.55 | W12: 13186.63 | X12: 3069.19 | Y12: 9271.01 | Z12: 24056.33 | AA12: 2539.58 | AB12: 2129.7 | AC12: 13750.97 | AD12: 84242.06 | AJ12: John Harper | AK12: 95154.19 | AM12: Chester George | AN12: 81915.97 | AQ12: Grand Total | AR12: 3186258.5
E13: 2024-09 | F13: 24828.08 | G13: 108649.16 | H13: 133477.24 | K13: 2024-10 | L13: 677.89044 | O13: Clothing & Fashion | P13: 686479.84 | S13: Campbelltown | T13: 1999.58 | U13: 6086.26 | V13: 9578.03 | W13: 16966.76 | X13: 4715.68 | Y13: 13497.35 | Z13: 23944.06 | AA13: 2804.74 | AB13: 2973.17 | AC13: 14879.73 | AD13: 97445.36 | AJ13: Ricky Wilkinson | AK13: 135254.32 | AM13: Elizabeth Gentry | AN13: 104554.16
E14: 2024-10 | F14: 17343.39 | G14: 106032.67 | H14: 123376.06 | K14: 2024-11 | L14: 561.492 | O14: Grand Total | P14: 3186258.5 | S14: Frankston | T14: 3846.59 | U14: 8076.25 | V14: 6997.02 | W14: 19061.78 | X14: 5277.63 | Y14: 15647.41 | Z14: 24951.05 | AA14: 3095.06 | AB14: 2289.82 | AC14: 16479.7 | AD14: 105722.31 | AJ14: Shellie Thomas | AK14: 139095.3 | AM14: Howard Wright | AN14: 121697.56
E15: 2024-11 | F15: 18723.63 | G15: 73922.55 | H15: 92646.18 | K15: 2024-12 | L15: 712.08754 | S15: Grand Total | T15: 20266.95 | U15: 50540.82 | V15: 80870.67 | W15: 133644.87 | X15: 36347.33 | Y15: 112910.36 | Z15: 202772.14 | AA15: 21182.11 | AB15: 20459.78 | AC15: 131259.45 | AD15: 810254.48 | AJ15: Miles Hammond | AK15: 149794.67 | AM15: Bruce Curran | AN15: 143924.37
E16: 2024-12 | F16: 31199.5 | G16: 96264.17 | H16: 127463.67 | K16: 2025-01 | L16: 615.71634 | AJ16: Claire Bridges | AK16: 158764.65 | AM16: Grand Total | AN16: 658115.49
E17: 2025-01 | F17: 27492.12 | G17: 80258.24 | H17: 107750.36 | K17: 2025-02 | L17: 673.86909 | AJ17: Brian Hubbard | AK17: 199582.91
E18: 2025-02 | F18: 24833.15 | G18: 85681.38 | H18: 110514.53 | K18: 2025-03 | L18: 696.86138 | AJ18: Terri Wright | AK18: 212338.27
E19: 2025-03 | F19: 10692.77 | G19: 105683.08 | H19: 116375.85 | K19: 2025-04 | L19: 658.08767 | AJ19: George Chester | AK19: 224691.45
E20: 2025-04 | F20: 38255.05 | G20: 88755.87 | H20: 127010.92 | K20: 2025-05 | L20: 637.82766 | AJ20: Jerry Fulton | AK20: 248771.27
E21: 2025-05 | F21: 29125.19 | G21: 99078.17 | H21: 128203.36 | K21: 2025-06 | L21: 491.04209 | AJ21: Jeremy Garcia | AK21: 253667.24
E22: 2025-06 | F22: 25348.78 | G22: 68440.26 | H22: 93789.04 | K22: 2025-07 | L22: 716.6948 | AJ22: Lillian Pruitt | AK22: 271081.19
E23: 2025-07 | F23: 25256.57 | G23: 103031.8 | H23: 128288.37 | K23: 2025-08 | L23: 1049.379 | AJ23: John Gardner | AK23: 296080.9
E24: 2025-08 | F24: 52893.44 | G24: 154883.61 | H24: 207777.05 | K24: 2025-09 | L24: 640.11033 | AJ24: Rachael Long | AK24: 309776.27
E25: 2025-09 | F25: 22345.94 | G25: 92873.92 | H25: 115219.86 | K25: 2025-10 | L25: 731.50422 | AJ25: Grand Total | AK25: 3186258.5
E26: 2025-10 | F26: 26766.3 | G26: 113682.51 | H26: 140448.81 | K26: 2025-11 | L26: 740.93105
E27: 2025-11 | F27: 38143.5 | G27: 103374.33 | H27: 141517.83 | K27: 2025-12 | L27: 686.11363
E28: 2025-12 | F28: 24775.33 | G28: 113133.51 | H28: 137908.84 | K28: Grand Total | L28: 707.27158
E29: Grand Total | F29: 658115.49 | G29: 2528143 | H29: 3186258.5
A33: Total Sales | B33: Month
A34: State | B34: 2024-01 | C34: 2024-02 | D34: 2024-03 | E34: 2024-04 | F34: 2024-05 | G34: 2024-06 | H34: 2024-07 | I34: 2024-08 | J34: 2024-09 | K34: 2024-10 | L34: 2024-11 | M34: 2024-12 | N34: 2025-01 | O34: 2025-02 | P34: 2025-03 | Q34: 2025-04 | R34: 2025-05 | S34: 2025-06 | T34: 2025-07 | U34: 2025-08 | V34: 2025-09 | W34: 2025-10 | X34: 2025-11 | Y34: 2025-12 | Z34: Grand Total
A35: ACT | B35: 2487.93 | C35: 31 | D35: 522.22 | E35: 2517.59 | F35: 547.48 | G35: 1882.32 | H35: 2351.43 | I35: 747.94 | J35: 859.16 | K35: 1291.51 | L35: 1043.02 | M35: 1358.68 | N35: 1261.25 | O35: 832.84 | P35: 102.8 | Q35: 1345.34 | R35: 2312.97 | S35: 3207.83 | T35: 8576.91 | U35: 91.25 | V35: 609.46 | W35: 3779.82 | X35: 57.8 | Y35: 863.41 | Z35: 38681.96
A36: NSW | B36: 34786.91 | C36: 53147.22 | D36: 47054.91 | E36: 65289.14 | F36: 42797.46 | G36: 75352.9 | H36: 43487.3 | I36: 52364.45 | J36: 36195.92 | K36: 36885.59 | L36: 29161.07 | M36: 53154.85 | N36: 46181.35 | O36: 32879.5 | P36: 54809.26 | Q36: 51842.82 | R36: 59859.29 | S36: 26656.73 | T36: 41840.67 | U36: 96334.98 | V36: 51098.7 | W36: 56519.55 | X36: 39642.65 | Y36: 38260.25 | Z36: 1165603.5
A37: NT | B37: 5444.25 | C37: 6893.44 | D37: 283.01 | E37: 2888.44 | F37: 3095.21 | G37: 1090.93 | H37: 3061.76 | I37: 1037.09 | J37: 1766.66 | K37: 5480.28 | L37: 1867.12 | M37: 975.43 | N37: 667.67 | O37: 375.27 | P37: 2939.04 | Q37: 1920.32 | R37: 1808.31 | S37: 207.42 | T37: 3318.26 | U37: 325.47 | V37: 9915.38 | W37: 325.86 | X37: 10540.67 | Y37: 1619.52 | Z37: 67846.81
A38: QLD | B38: 20657.06 | C38: 23682.34 | D38: 24229.68 | E38: 27449.05 | F38: 38339.41 | G38: 43033.21 | H38: 19780.93 | I38: 38129.71 | J38: 44197.53 | K38: 5681.13 | L38: 23206.23 | M38: 18849.86 | N38: 24303.97 | O38: 25062.28 | P38: 13944.38 | Q38: 27965.3 | R38: 24158.3 | S38: 28111.27 | T38: 22330.28 | U38: 19140.33 | V38: 15295.26 | W38: 16906.9 | X38: 30509.22 | Y38: 28901.35 | Z38: 603864.98
A39: SA | B39: 6127.46 | C39: 2657.02 | D39: 1639.22 | E39: 3449.05 | F39: 2693.26 | G39: 4159.73 | H39: 3013.54 | I39: 5542.8 | J39: 4511.49 | K39: 7133.27 | L39: 4808.09 | M39: 4008.05 | N39: 3172.76 | O39: 5262.75 | P39: 3046.49 | Q39: 6725.42 | R39: 1583.25 | S39: 5915.53 | T39: 8457.03 | U39: 5144.95 | V39: 5652.97 | W39: 6560.21 | X39: 6358.13 | Y39: 5093.8 | Z39: 112716.27
A40: TAS | B40: 2982.14 | C40: 3427.43 | D40: 552.32 | E40: 2185 | F40: 3372.03 | G40: 1828.1 | H40: 1840.51 | I40: 2493.61 | J40: 4015.02 | K40: 2474.28 | L40: 2305.18 | M40: 2311.21 | N40: 2810.88 | O40: 3643.46 | P40: 7370.86 | Q40: 2103.99 | R40: 1498.65 | S40: 2758.87 | T40: 783.95 | U40: 456.23 | V40: 4576.73 | W40: 1710.28 | X40: 1347.56 | Y40: 664.16 | Z40: 59512.45
A41: VIC | B41: 39578.92 | C41: 27773.33 | D41: 39689.17 | E41: 57017.14 | F41: 21766.87 | G41: 38197.99 | H41: 47882.67 | I41: 38629.98 | J41: 35624.46 | K41: 35095.76 | L41: 22766.99 | M41: 36863.53 | N41: 22197.23 | O41: 29964.02 | P41: 22233.41 | Q41: 28750.12 | R41: 28477.1 | S41: 16526.49 | T41: 32150.34 | U41: 66180.38 | V41: 16808.3 | W41: 38666.62 | X41: 34258.49 | Y41: 48350.01 | Z41: 825449.32
A42: WA | B42: 18731.56 | C42: 14918.71 | D42: 6816.86 | E42: 9888.02 | F42: 11914.76 | G42: 23421.41 | H42: 12298.1 | I42: 13538.08 | J42: 6307 | K42: 29334.24 | L42: 7488.48 | M42: 9942.06 | N42: 7155.25 | O42: 12494.41 | P42: 11929.61 | Q42: 6357.61 | R42: 8505.49 | S42: 10404.9 | T42: 10830.93 | U42: 20103.46 | V42: 11263.06 | W42: 15979.57 | X42: 18803.31 | Y42: 14156.34 | Z42: 312583.22
A43: Grand Total | B43: 130796.23 | C43: 132530.49 | D43: 120787.39 | E43: 170683.43 | F43: 124526.48 | G43: 188966.59 | H43: 133716.24 | I43: 152483.66 | J43: 133477.24 | K43: 123376.06 | L43: 92646.18 | M43: 127463.67 | N43: 107750.36 | O43: 110514.53 | P43: 116375.85 | Q43: 127010.92 | R43: 128203.36 | S43: 93789.04 | T43: 128288.37 | U43: 207777.05 | V43: 115219.86 | W43: 140448.81 | X43: 141517.83 | Y43: 137908.84 | Z43: 3186258.5
A46: MAP DATA: select A47:C55, then Insert > Maps > Filled Map (live: follows the slicers via GETPIVOTDATA)
...

Sheet Raw Data (Unclean)
A1: Date | B1: Financial Year | C1: Financial Year2 | D1: Type | E1: Suburb | F1: Full State | G1: State | H1: Postcode | I1: Country | J1: Manager | K1: Category | L1: Buyer | M1: Sales
A2: 45476 | B2: 2025 | C2: 2024-2025 | D2: KMART STORE | F2: Western Australia | G2: WA | H2: 6021 | I2: Australia | J2: Tom McKenzie | K2: Beauty & Personal Care | L2: Chester George | M2: 1
A3: 03rdDec2024 | D3: KMART STORE | E3: Ballina | F3: New South Wales | G3: NSW | I3: Australia | J3: Claire Bridges | K3: Home & Living | L3: Elizabeth Gentry | M3: 1
A4: 45416 | B4: 2024 | C4: 2023-2024 | D4: KMART ONLINE | E4: Belconnen | F4: Australian Capital Territory | G4: ACT | H4: 2617 | I4: Australia | J4: George Chester | K4: Home & Living | L4: Elizabeth Gentry | M4: 1
A5: 45801 | B5: 2025 | C5: 2024-2025 | D5: KMART STORE | E5: Burleigh Waters | F5: Queensland | G5: QLD | H5: 4220 | I5: Australia | J5: Ricky Wilkinson | K5: Accessories | L5: Sara Ferrell | M5: 1
A6: 45536 | B6: 2025 | C6: 2024-2025 | D6: KMART STORE | E6: Castle Hill | F6: New South Wales | G6: NSW | H6: 2154 | I6: Australia | J6: Lillian Pruitt | K6: Baby & Nursery | L6: Amy Buchanan | M6: 1
A7: 45574 | B7: 2025 | C7: 2024-2025 | D7: KMART STORE | E7: Chatswood | F7: New South Wales | G7: NSW | I7: Australia | J7: Jeremy Garcia | K7: Beauty & Personal Care | L7: Chester George | M7: 1
A8: 45333 | B8: 2024 | C8: 2023-2024 | D8: KMART STORE | E8: Claremont | F8: Western Australia | G8: WA | H8: 6010 | I8: Australia | J8: Tom McKenzie | K8: Clothing & Fashion | L8: Bruce Curran | M8: 1
A9: 45594 | B9: 2025 | C9: 2024-2025 | D9: KMART STORE | E9: Dandenong | F9: Victoria | G9: VIC | H9: 3175 | I9: Australia | J9: Rachael Long | K9: Home & Living | L9: Elizabeth Gentry | M9: 1
A10: 45661 | B10: 2025 | C10: 2024-2025 | D10: KMART STORE | E10: Dural | F10: New South Wales | G10: NSW | H10: 2158 | I10: Australia | J10: Lillian Pruitt | K10: Baby & Nursery | L10: Amy Buchanan | M10: 1
A11: 45779 | B11: 2025 | C11: 2024-2025 | D11: KMART STORE | E11: Epping | F11: Victoria | G11: VIC | H11: 3076 | I11: Australia | J11: Brian Hubbard | K11: Electronics & Entertainment | L11: Maggie Mayer | M11: 1
A12: 45673 | B12: 2025 | C12: 2024-2025 | D12: KMART STORE | E12: Epping | F12: Victoria | G12: VIC | H12: 3076 | I12: Australia | J12: Brian Hubbard | K12: Beauty & Personal Care | L12: Chester George | M12: 1
A13: 13thOct2024 | D13: KMART STORE | E13: Epsom | F13: Victoria | G13: VIC | I13: Australia | J13: Jerry Fulton | K13: Stationery & Office Supplies | L13: Ella Hickman | M13: 1
A14: 45606 | B14: 2025 | C14: 2024-2025 | D14: KMART STORE | E14: Glenorchy | F14: Tasmania | G14: TAS | H14: 7010 | I14: Australia | J14: Simone Prior | K14: Beauty & Personal Care | L14: Chester George | M14: 1
A15: 45566 | B15: 2025 | C15: 2024-2025 | D15: KMART STORE | E15: Indooroopilly | F15: Queensland | G15: QLD | H15: 4068 | I15: Australia | J15: Terri Wright | K15: Home & Living | L15: Elizabeth Gentry | M15: 1
A16: 45621 | B16: 2025 | C16: 2024-2025 | D16: KMART STORE | E16: Lismore | F16: New South Wales | G16: NSW | H16: 2480 | I16: Australia | J16: Claire Bridges | K16: Home & Living | L16: Elizabeth Gentry | M16: 1
A17: 45634 | B17: 2025 | C17: 2024-2025 | D17: KMART STORE | E17: Lithgow | F17: New South Wales | G17: NSW | H17: 2790 | I17: Australia | J17: John Gardner | K17: Home & Living | L17: Elizabeth Gentry | M17: 1
A18: 45317 | B18: 2024 | C18: 2023-2024 | D18: KMART STORE | E18: Mascot | F18: New South Wales | G18: NSW | H18: 2020 | I18: Australia | J18: Jeremy Garcia | K18: Electronics & Entertainment | L18: Maggie Mayer | M18: 1
A19: 45568 | B19: 2025 | C19: 2024-2025 | D19: KMART ONLINE | E19: Mindarie | F19: Western Australia | G19: WA | H19: 6030 | I19: Australia | J19: Tom McKenzie | K19: Baby & Nursery | L19: Amy Buchanan | M19: 1
A20: 45586 | B20: 2025 | C20: 2024-2025 | D20: KMART ONLINE | E20: Mindarie | F20: Western Australia | G20: WA | H20: 6030 | I20: Australia | J20: Tom McKenzie | K20: Baby & Nursery | L20: Amy Buchanan | M20: 1
A21: 45504 | B21: 2025 | C21: 2024-2025 | D21: KMART STORE | E21: Mt Isa | F21: Queensland | G21: QLD | H21: 4825 | I21: Australia | J21: Caroline Tucker | K21: Footwear | L21: Richard Carr | M21: 1
A22: 45528 | B22: 2025 | C22: 2024-2025 | D22: KMART STORE | E22: Noarlunga | F22: South Australia | G22: SA | H22: 5168 | I22: Australia | J22: Ray Watson | K22: Baby & Nursery | L22: Amy Buchanan | M22: 1
A23: 45434 | B23: 2024 | C23: 2023-2024 | D23: KMART STORE | E23: Orange | F23: New South Wales | G23: NSW | H23: 2800 | I23: Australia | J23: John Gardner | K23: Electronics & Entertainment | L23: Maggie Mayer | M23: 1
A24: 45459 | B24: 2024 | C24: 2023-2024 | D24: KMART STORE | E24: Sunbury | F24: Victoria | G24: VIC | H24: 3429 | I24: Australia | J24: Jerry Fulton | K24: Baby & Nursery | L24: Amy Buchanan | M24: 1
A25: 45974 | B25: 2026 | C25: 2025-2026 | D25: KMART STORE | E25: Toombul | F25: Queensland | G25: QLD | H25: 4012 | I25: Australia | J25: Terri Wright | K25: Baby & Nursery | L25: Amy Buchanan | M25: 1
... A202: 45829 | B202: 2025 | C202: 2024-2025 | D202: KMART STORE | E202: Frankston | F202: Victoria | G202: VIC | H202: 3199 | I202: Australia | J202: Rachael Long | K202: Home & Living | L202: Elizabeth Gentry | M202: 4.96
A203: 45808 | B203: 2025 | C203: 2024-2025 | D203: KMART STORE | F203: Western Australia | G203: WA | H203: 6021 | I203: Australia | J203: Tom McKenzie | K203: Footwear | L203: Richard Carr | M203: 4.99
A204: 45446 | B204: 2024 | C204: 2023-2024 | D204: KMART STORE | E204: Bussleton | F204: Western Australia | G204: WA | H204: 6280 | I204: Australia | J204: Miles Hammond | K204: Electronics & Entertainment | L204: Maggie Mayer | M204: 4.99
A205: 45962 | B205: 2026 | C205: 2025-2026 | D205: KMART STORE | E205: Claremont | F205: Western Australia | G205: WA | H205: 6010 | I205: Australia | J205: Tom McKenzie | K205: Electronics & Entertainment | L205: Maggie Mayer | M205: 4.99
A206: 45790 | B206: 2025 | C206: 2024-2025 | D206: KMART STORE | E206: Cranbourne | F206: Victoria | G206: VIC | H206: 3977 | I206: Australia | J206: Owen Pierce | K206: Footwear | L206: Richard Carr | M206: 4.99
A207: 45404 | B207: 2024 | C207: 2023-2024 | D207: KMART STORE | E207: Dubbo | F207: New South Wales | G207: NSW | H207: 2830 | I207: Australia | J207: John Gardner | K207: Electronics & Entertainment | L207: Maggie Mayer | M207: 4.99
A208: 45552 | B208: 2025 | C208: 2024-2025 | D208: KMART STORE | E208: Dural | F208: New South Wales | G208: NSW | H208: 2158 | I208: Australia | J208: Lillian Pruitt | K208: Electronics & Entertainment | L208: Maggie Mayer | M208: 4.99
A209: 45825 | B209: 2025 | C209: 2024-2025 | D209: KMART STORE | E209: Dural | F209: New South Wales | G209: NSW | H209: 2158 | I209: Australia | J209: Lillian Pruitt | K209: Clothing & Fashion | L209: Bruce Curran | M209: 4.99
A210: 45504 | B210: 2025 | C210: 2024-2025 | D210: KMART STORE | E210: Hervey Bay | F210: Queensland | G210: QLD | H210: 4655 | I210: Australia | J210: Amber Ward | K210: Electronics & Entertainment | L210: Maggie Mayer | M210: 4.99
A211: 45359 | B211: 2024 | C211: 2023-2024 | D211: KMART STORE | E211: Maroochydore | F211: Queensland | G211: QLD | H211: 4558 | I211: Australia | J211: Shellie Thomas | K211: Clothing & Fashion | L211: Bruce Curran | M211: 4.99
A212: 45991 | B212: 2026 | C212: 2025-2026 | D212: KMART ONLINE | E212: Southport | F212: Queensland | G212: QLD | H212: 4215 | I212: Australia | J212: Ricky Wilkinson | K212: Clothing & Fashion | L212: Bruce Curran | M212: 4.99
A213: 45606 | B213: 2025 | C213: 2024-2025 | D213: KMART STORE | E213: Stafford | F213: Queensland | G213: QLD | H213: 4053 | I213: Australia | J213: Terri Wright | K213: Clothing & Fashion | L213: Bruce Curran | M213: 4.99
A214: 45658 | B214: 2025 | C214: 2024-2025 | D214: KMART STORE | E214: Airlie Beach | F214: Queensland | G214: QLD | H214: 4802 | I214: Australia | J214: Caroline Tucker | K214: Electronics & Entertainment | L214: Maggie Mayer | M214: 5
A215: 45852 | B215: 2026 | C215: 2025-2026 | D215: KMART ONLINE | E215: Caloundra | F215: Queensland | G215: QLD | H215: 4551 | I215: Australia | J215: Shellie Thomas | K215: Toys & Outdoor Play | L215: Howard Wright | M215: 5
... A4506: 45325 | B4506: 2024 | C4506: 2023-2024 | D4506: KMART STORE | E4506: Campbelltown | F4506: New South Wales | G4506: NSW | H4506: 2560 | I4506: Australia | J4506: George Chester | K4506: Home & Living | L4506: Elizabeth Gentry | M4506: 12653.07

Sheet Notes
A1: How this workbook works
A3: Main Dashboard | B3: One-screen dashboard. The 4 slicers (Financial Year, Type, State, Category) are connected to every pivot table, so one click filters both KPI cards and all charts.
A4: KMART DATA | B4: Cleaned master table (Excel table "KMART_DATA"). Financial Year, Month and Full State are formulas. Add rows at the bottom of the table and they are picked up automatically.
A5: Pivots | B5: One pivot table per visual, all sharing a single pivot cache. KPI cards, the state table, the map and the sparklines read from these pivots with GETPIVOTDATA, so nothing is hardcoded.
A6: Refreshing | B6: Pivots refresh automatically every time the file is opened. After editing data while the file is open, use Data > Refresh All.
A7: Exception: buyers chart | B7: "Sales by buyers - online" is fixed to Online sales, so the Type slicer is deliberately not connected to it; the other three slicers are.
A8: Category-mix chart | B8: There are 97 suburbs, too many to read as bars, so the 100% stacked chart shows the top 10 suburbs by sales for the current slicer selection (pivot Top 10 filter).
A9: Filled map | B9: Excel must create filled maps itself (it embeds Bing map data). On the Pivots sheet select A47:C55, then Insert > Maps > Filled Map, cut the chart and paste it over "Sales by state" on the dashboard. It stays live because A47:C55 reads the slicer-filtered state pivot. Needs Excel 2019 / Microsoft 365 and internet.
A10: Colours | B10: Brand palette from the Kmart guidelines is set as the workbook theme: Ocean Deep blue = Online / single-series, Primary Scarlet red = Store. The 10-category mix chart needs more than two colours, so it uses the brand supplementary palette.
A12: Data cleaning log (raw sheet -> KMART DATA)
A14: Date | B14: 2 dates stored as text (e.g. "03rdDec2024") converted to real dates.
A15: Type | B15: "KMART ONLINE"/"KMART STORE" shortened to "Online"/"Store" for slicers and legends.
A16: Suburb | B16: 2 blank suburbs filled from postcode (each postcode maps to exactly one suburb in the data).
A17: Postcode | B17: 3 blank postcodes filled from suburb; postcodes stored as 4-digit text so NT codes keep their leading zero (800 -> "0800").
A18: Financial Year | B18: 2 blank values. Column is now a formula derived from Date (Australian FY, July-June), labelled e.g. "FY2024-25".
A19: Month | B19: New formula column (e.g. "2024-07") used for the month/year trend charts.
A20: Full State | B20: Formula derived from the State code, so it can never drift from State.
A21: Financial Year2 | B21: Dropped - duplicated Financial Year.
A22: Checks | B22: No duplicate rows, no negative or zero sales, no stray whitespace found. Row count unchanged (4,505).
